Workbook

Sheet MASTER
A2: Head of Account | B2: Address | C2: Address | D2: Phone | E2: City | F2: GST # | G2: PAN | H2: State | I2: pincode
A3: .Kulvir Singh | B3: Aadhar Card No. 781828029617 | D3: =IFERROR(VLOOKUP(A3, Sheet2!A:C, 3, FALSE), "") | E3: Ludhiana | H3: PUNJAB | I3: 141001
A4: 50 Shades | B4: Awantipora | D4: =IFERROR(VLOOKUP(A4, Sheet2!A:B, 2, FALSE), "") | E4: Awantipora | H4: JAMMU & KASHMIR | I4: 192122 | J4: Jammu
A5: A K Traders | B5: Chd Landran Road | D5: =IFERROR(VLOOKUP(A5, Sheet2!A:B, 2, FALSE), "") | E5: Sector-77 | F5: 03AAHPV4566B1ZS | G5: AAHPV4566B | H5: PUNJAB | I5: 140308 | J5: Sas Nagar
A6: A M Multi Packaging Private Limited | B6: Plot No. 34 Hsiidc | C6: SECTOR-56 | D6: =IFERROR(VLOOKUP(A6, Sheet2!A:B, 2, FALSE), "") | E6: Kundli | F6: 06AAICA1075C1Z5 | G6: AAICA1075C | H6: HARYANA | I6: 131028 | J6: Sonipat
A7: A S Associates | B7: Ranbirsinghpora | C7: =IFERROR(VLOOKUP(A8, Sheet2!A:B, 2, FALSE), "") | D7: =IFERROR(VLOOKUP(A7, Sheet2!A:B, 2, FALSE), "") | E7: Jammu | F7: 01ACBFA0779R1Z8 | G7: ACBFA0779R | H7: JAMMU & KASHMIR | I7: 181102 | J7: Jammu
A8: A-1 Industries | B8: A-1 Industries | C8: Near Shiv Oil Company Bpcl Petrol Pump | E8: Khanna | F8: 03ABZPG5414E1ZS | G8: ABZPG5414E | H8: PUNJAB | I8: 141401 | J8: Ludhiana
A9: A-one Tex Tech Pvt. Ltd. | B9: Plot No-2046 | C9: Phase-ii | D9: =IFERROR(VLOOKUP(A9, Sheet2!A:B, 2, FALSE), "") | E9: Sonipat | F9: 06AAJCA4367Q1Z2 | G9: AAJCA4367Q | H9: HARYANA | I9: 131029 | J9: Sonipat
A10: A.D LOGISTICS LDH | B10: CHHATTISGARH | D10: =IFERROR(VLOOKUP(A10, Sheet2!A:B, 2, FALSE), "") | F10: 07ACAFA9584F1Z9 | G10: ACAFA9584F | H10: DELHI
A11: A.V TEXTILES | B11: M.B.D MAKT. SHOP NO.12, | C11: NEAR CIVIL HOSPITAL, | D11: =IFERROR(VLOOKUP(A11, Sheet2!A:B, 2, FALSE), "") | E11: Jalandhar | F11: 03AECPG8013K1ZV | G11: AECPG8013K | H11: PUNJAB | I11: 144001 | J11: Jalandhar
A12: A.a.packaging | B12: 275 | D12: =IFERROR(VLOOKUP(A12, Sheet2!A:B, 2, FALSE), "") | E12: Vasant Vihar,karnal | F12: 06ABIFA9469L1ZS | G12: ABIFA9469L | H12: HARYANA | I12: 132001 | J12: Karnal
A13: Aastha Marketing | B13: 1, INFRONT OF SIVAM PALACE | C13: Jawahar Nagar Bichhiya | D13: =IFERROR(VLOOKUP(A13, Sheet2!A:B, 2, FALSE), "") -> 9993560225 | E13: Rewa | F13: 23BWRPK0849P1ZU | G13: BWRPK0849P | H13: MADHYA PRADESH | I13: 486001 | J13: Rewa
A14: Abaan Packaging | B14: 04/2500-2507,,NANI BEGUMWADI, | C14: Near Mukti Dham Mandir | D14: =IFERROR(VLOOKUP(A14, Sheet2!A:B, 2, FALSE), "") -> 9825776004 | E14: Salabatpura | F14: 24AGUPC3612L1ZC | G14: AGUPC3612L | H14: GUJRAT | I14: 395003 | J14: Surat
A15: Abhishek Transport Corporation | B15: Abhishek Transport Corporation | C15: Transpoprt Nagar | D15: =IFERROR(VLOOKUP(A15, Sheet2!A:B, 2, FALSE), "") | E15: Ludhiana | F15: 03AGJPK5039N2Z5 | G15: AGJPK5039N | H15: PUNJAB | I15: 141008 | J15: Ludhiana
A16: Abr Parcel Service | B16: B-23/2818 | D16: =IFERROR(VLOOKUP(A16, Sheet2!A:B, 2, FALSE), "") | E16: Transport Nagar | F16: 03ABZPC2933Q1Z5 | G16: ABZPC2933Q | H16: PUNJAB | I16: 141003 | J16: Ludhiana
A17: Ace International | B17: 154, Cycle Shopping Centre | C17: Gill Road | D17: =IFERROR(VLOOKUP(A17, Sheet2!A:B, 2, FALSE), "") | E17: Ludhiana | F17: 03AEVPG1115M1ZJ | G17: AEVPG1115M | H17: PUNJAB | I17: 141003 | J17: Ludhiana
A18: Aditi Enterprises | D18: =IFERROR(VLOOKUP(A18, Sheet2!A:B, 2, FALSE), "") | H18: PUNJAB
A19: Aditya Creations | B19: Sadar Bazar | D19: =IFERROR(VLOOKUP(A19, Sheet2!A:B, 2, FALSE), "") | E19: Shahjahanpur | F19: 09JSMPK2274K1Z0 | G19: JSMPK2274K | H19: UTTAR PRADESH | I19: 242001 | J19: Shahjahanpur
A20: Aditya Nonwoven Fabrics Private Limited | B20: Plot No 18 | C20: Sector 21 | D20: =IFERROR(VLOOKUP(A20, Sheet2!A:B, 2, FALSE), "") | E20: Bhiwani | F20: 06AAJCA2941C1Z3 | G20: AAJCA2941C | H20: HARYANA | I20: 127021 | J20: Bhiwani
A21: Advance Tax / TDS | D21: =IFERROR(VLOOKUP(A21, Sheet2!A:B, 2, FALSE), "")
A22: Advertisment | D22: =IFERROR(VLOOKUP(A22, Sheet2!A:B, 2, FALSE), "")
A23: Agam Textile | B23: Khasra No. 886/130 | C23: Agam Textile | D23: =IFERROR(VLOOKUP(A23, Sheet2!A:B, 2, FALSE), "") | E23: Jalandhar | F23: 03BLAPS0025B1Z0 | G23: BLAPS0025B | H23: PUNJAB | I23: 144002 | J23: Jalandhar
A24: Aggarwal Hosiery Factory | B24: 7078 | C24: Guru Nanak Gali, Ashok Bazar | D24: =IFERROR(VLOOKUP(A24, Sheet2!A:B, 2, FALSE), "") | E24: Delhi | F24: 07AOHPK2987H1ZL | G24: AOHPK2987H | H24: DELHI | I24: 110031 | J24: North East Delhi
A25: Aggarwal Trading Company | B25: Shop | C25: Aggarwal Trading Company | D25: =IFERROR(VLOOKUP(A25, Sheet2!A:B, 2, FALSE), "") | E25: Village Kumbra Near Forest Complex | F25: 03CTTPM8819B1ZG | G25: CTTPM8819B | H25: PUNJAB | I25: 140308 | J25: Sas Nagar
A26: Agrimtechzone | B26: 98880-01691 | C26: MAIN BAZAR,NEAR POST OFFICE | D26: =IFERROR(VLOOKUP(A26, Sheet2!A:B, 2, FALSE), "") | E26: Pathankot | F26: 03AEJPM3993H1ZA | G26: AEJPM3993H | H26: PUNJAB | I26: 145001 | J26: Pathankot
A27: Ahuja Dresses | B27: Karan Adhaar No. 514443109565 | C27: St No. 6/2 Lajpat Nagar,Bajra | D27: =IFERROR(VLOOKUP(A27, Sheet2!A:B, 2, FALSE), "") | E27: Ludhiana | H27: PUNJAB | I27: 141007
A28: Ahuja Garments | B28: RAILWAY ROAD, BARARA | D28: =IFERROR(VLOOKUP(A28, Sheet2!A:B, 2, FALSE), "") | E28: Barara | F28: 06ADZPS0684G1ZW | G28: ADZPS0684G | H28: HARYANA | I28: 133201 | J28: Ambala
A29: Ahuja Sons | B29: Shop.no.b-16-59/85 | C29: Ahuja Sons | D29: =IFERROR(VLOOKUP(A29, Sheet2!A:B, 2, FALSE), "") | E29: Ahluwalia Street | F29: 03ACJPA0936C1ZF | G29: ACJPA0936C | H29: PUNJAB | I29: 141001 | J29: Ludhiana
A30: Air Conditioner | D30: =IFERROR(VLOOKUP(A30, Sheet2!A:B, 2, FALSE), "")
A31: Aira Knitwears | B31: B-5-617 | C31: Wait Ganj | D31: =IFERROR(VLOOKUP(A31, Sheet2!A:B, 2, FALSE), "") -> 8360316861 | E31: Ludhiana | F31: 03BUIPS4332J1ZJ | G31: BUIPS4332J | H31: PUNJAB | I31: 141008 | J31: Ludhiana
A32: Ajanta Collections | B32: Sirsa | D32: =IFERROR(VLOOKUP(A32, Sheet2!A:B, 2, FALSE), "") | E32: Rori Bazar | F32: 06AAKFA1451B1Z3 | G32: AAKFA1451B | H32: HARYANA | I32: 125055 | J32: Sirsa
A33: Ajay Bags Manufacturer | B33: 124 | D33: =IFERROR(VLOOKUP(A33, Sheet2!A:B, 2, FALSE), "") -> 8250125512 | E33: Kolkata | F33: 19DMXPP0113D1ZY | G33: DMXPP0113D | H33: WEST BENGAL | I33: 700083 | J33: North Twenty Four Pargana
A34: Ajay Hardware Sanitary House | B34: 48/10 | D34: =IFERROR(VLOOKUP(A34, Sheet2!A:B, 2, FALSE), "") | E34: Payal | F34: 03AIWPK1286E1Z6 | G34: AIWPK1286E | H34: PUNJAB | I34: 141002 | J34: Ludhiana
A35: Ajeet Arts | B35: 406 | C35: Reena Apartment | D35: =IFERROR(VLOOKUP(A35, Sheet2!A:B, 2, FALSE), "") -> 9820427369 | E35: Malad West | F35: 27AMYPS0324H1ZN | G35: AMYPS0324H | H35: MAHARASHTRA | I35: 400064 | J35: Mumbai Suburban
A36: Ajit Goods Carrier | B36: Namaste Chowk | D36: =IFERROR(VLOOKUP(A36, Sheet2!A:B, 2, FALSE), "") | E36: Karnal | F36: 06BDOPS3894N1ZH | G36: BDOPS3894N | H36: HARYANA | I36: 132001 | J36: Karnal
A37: Ajit Mills (ams) | B37: Village Nicchi Mangli | C37: Chd. Road | D37: =IFERROR(VLOOKUP(A37, Sheet2!A:B, 2, FALSE), "") -> 9261240004 | E37: Ludhiana | F37: 03AAEPH8526Q1ZE | G37: AAEPH8526Q | H37: PUNJAB | I37: 141010 | J37: Ludhiana
A38: Ajooni Biotech Limited | B38: Near Gaib Di Pully | C38: Phase Vii | D38: =IFERROR(VLOOKUP(A38, Sheet2!A:B, 2, FALSE), "") | E38: Khanna | F38: 03AAMCA2765P1Z9 | G38: AAMCA2765P | H38: PUNJAB | I38: 141401 | J38: Ludhiana
A39: Akaal Sahai Enterprises | B39: 17A RAM NAGAR | D39: =IFERROR(VLOOKUP(A39, Sheet2!A:B, 2, FALSE), "") | E39: Ambala Cantt | F39: 06AKPPS6084D1ZR | G39: AKPPS6084D | H39: HARYANA | I39: 133001 | J39: Ambala
A40: Akanksha Fabrics | B40: Village Ayali Khurd | C40: Hambran Road | D40: =IFERROR(VLOOKUP(A40, Sheet2!A:B, 2, FALSE), "") -> 9779160685 | E40: Ludhiana | F40: 03AAFFA1911P1ZO | G40: AAFFA1911P | H40: PUNJAB | I40: 141001 | J40: Ludhiana
A41: Al-qamar Graphics | B41: MURRAN CHOWK | D41: 9103101774 | E41: Pulwama | F41: 01ABSFA0055A1Z7 | G41: ABSFA0055A | H41: JAMMU & KASHMIR | I41: 192301 | J41: Pulwama
...

Sheet Sheet2
A1: AASTHA MARKETING | B1: 9993560225 | C1: Agent | D1: A | E1: Parminder
A2: ABAAN PACKAGING | B2: 9825776004 | C2: Agent | D2: A | E2: Jyoti
A3: AIRA KNITWEARS | B3: 8360316861 | C3: Customer | D3: A | E3: RAVI LDH
A4: AJAY BAGS MANUFACTURER | B4: 8250125512 | C4: Agent | D4: A | E4: Parminder
A5: AJEET ARTS | B5: 9820427369 | C5: Customer | D5: A | E5: Purchase
A6: AJIT MILLS (AMS) | B6: 9261240004 | C6: Customer | D6: A | E6: Dinesh
A7: AKANKSHA FABRICS | B7: 9779160685 | C7: Customer | D7: A | E7: Dinesh
A8: AL QAMAR GRAPHICS | B8: 9103101774 | C8: Agent | D8: A | E8: Parminder
A9: AMAR GARMENTS AND JEWELLERY | B9: 8676885999 | C9: Customer | D9: A | E9: Jyoti
A10: AMIN- BIN-KHALIK IMPEX (ABK IMPEX) | B10: 9906598692 | C10: Customer | D10: A | E10: Gourav
A11: ANAND AND COMPANY | B11: 8709914084 | C11: Agent | D11: A | E11: Parminder
A12: ANAND PALACE | B12: 9815484107 | C12: Customer | D12: A | E12: Dinesh
... A24: BALA JI BAGS AND PRINTING | B24: 6200506453 | C24: Agent | D24: A | E24: Parminder
A25: BANSAL NEW KKC | B25: 0000000000 | C25: Customer | D25: B | E25: Parminder
A26: BANSAL POLYMER | B26: 9803400071 | C26: Agent | D26: A | E26: Parminder
A27: BATRA GARMENTS PRIVATE LIMITED | B27: 9268116660 | C27: Customer | D27: A | E27: Parminder
A28: BATRA SILK AND SAREE | B28: 9872851000 | C28: Customer | D28: A | E28: Dinesh
A29: BATRA SILK STORE | B29: 9876600010 | C29: Customer | D29: A | E29: Dinesh
A30: BATTU PLAZA | B30: 7696664616 | C30: Customer | D30: A | E30: Purchase
A31: BAWA LEATHER POINT | B31: 9872492217 | C31: Customer | D31: A | E31: Gourav
A32: BEDI FASHION SHOPPEE | B32: 9876240929 | C32: Customer | D32: A | E32: RAVI LDH
A33: BEDI WORLD FASHION | B33: 9988009536 | C33: Customer | D33: A | E33: RAVI LDH
A34: BHAPE DI HATTI | B34: 9780234696 | C34: Customer | D34: A | E34: RAVI LDH
A35: BHARGAVA SHOES | B35: 9041930007 | C35: Customer | D35: A | E35: Parminder
A36: BHOMIA HOSIERY MILLS | B36: 9915117722 | C36: Customer | D36: A | E36: Jyoti
A37: BHOOMI INTERNATIONAL | B37: 9896042097 | C37: Customer | D37: A | E37: Parminder
... A250: ZIAMA FASHIONS PVT LTD | B250: 9876004495 | C250: Customer | D250: A | E250: RAVI LDH
